Exception on /news/archive [GET]
Traceback (most recent call last):
  File "/usr/lib/python3.4/site-packages/flask/app.py", line 1817, in wsgi_app
    response = self.full_dispatch_request()
  File "/usr/lib/python3.4/site-packages/flask/app.py", line 1477, in full_dispatch_request
    rv = self.handle_user_exception(e)
  File "/usr/lib/python3.4/site-packages/flask/app.py", line 1381, in handle_user_exception
    reraise(exc_type, exc_value, tb)
  File "/usr/lib/python3.4/site-packages/flask/_compat.py", line 33, in reraise
    raise value
  File "/usr/lib/python3.4/site-packages/flask/app.py", line 1475, in full_dispatch_request
    rv = self.dispatch_request()
  File "/usr/lib/python3.4/site-packages/flask/app.py", line 1461, in dispatch_request
    return self.view_functions[rule.endpoint](**req.view_args)
  File "/mnt/truecrypt1/Misc/7952/Website/pyfsw/views/news.py", line 37, in route_news_archive
    dicks()
NameError: name 'dicks' is not defined
